[
  {
    "time": 1741875133394,
    "function_name": "execute_immediate_return_command",
    "arguments": "{'command': 'ls -la /home/kavia/workspace/Authentication-server-I.0.3/', 'working_directory': '/home/kavia/workspace/Authentication-server-I.0.3'}",
    "reason": "Checking if the other required files already exist and what directories are present",
    "observations": "Need to check the current state of the project directory",
    "root_cause_analysis": "",
    "data": "",
    "is_error": false
  },
  {
    "time": 1741875204661,
    "function_name": "execute_immediate_return_command",
    "arguments": "{'working_directory': '/home/kavia/workspace/Authentication-server-I.0.3', 'command': 'mkdir -p auth_core/models auth_core/services auth_core/utils auth_core/config auth_core/tests && touch auth_core/__init__.py auth_core/models/__init__.py auth_core/services/__init__.py auth_core/utils/__init__.py auth_core/config/__init__.py auth_core/tests/__init__.py'}",
    "reason": "Creating the auth_core directory structure with all required subdirectories",
    "observations": "Creating the directory structure for the authentication core module",
    "root_cause_analysis": "",
    "data": "",
    "is_error": false
  },
  {
    "time": 1741875287086,
    "function_name": "execute_immediate_return_command",
    "arguments": "{'working_directory': '/home/kavia/workspace/Authentication-server-I.0.3', 'command': 'find auth_core -type f -name \"*.py\" | sort'}",
    "reason": "Verifying that the directory structure was created correctly",
    "observations": "Checking that all __init__.py files were created in the directory structure",
    "root_cause_analysis": "",
    "data": "",
    "is_error": false
  },
  {
    "time": 1741875386000,
    "function_name": "execute_immediate_return_command",
    "arguments": "{'command': 'find /home/kavia/workspace/Authentication-server-I.0.3/auth_core -type f | sort', 'working_directory': '/home/kavia/workspace/Authentication-server-I.0.3'}",
    "reason": "Need to check the existing directory structure to understand what files already exist and what needs to be created.",
    "observations": "No previous failures. Need to understand the current project structure.",
    "root_cause_analysis": "",
    "data": "",
    "is_error": false
  },
  {
    "time": 1741875560526,
    "function_name": "execute_immediate_return_command",
    "arguments": "{'working_directory': '/home/kavia/workspace/Authentication-server-I.0.3', 'command': 'python test_db.py'}",
    "reason": "Running the test script to verify that our database and models implementation works correctly.",
    "observations": "Testing the functionality of our database and models implementation.",
    "root_cause_analysis": "",
    "data": "",
    "is_error": false
  },
  {
    "time": 1741875580464,
    "function_name": "execute_immediate_return_command",
    "arguments": "{'working_directory': '/home/kavia/workspace', 'command': 'which python3'}",
    "reason": "Checking available Python versions to run our test script.",
    "observations": "Checking if python3 is available in the system.",
    "root_cause_analysis": "",
    "data": "",
    "is_error": false
  },
  {
    "time": 1741875589919,
    "function_name": "execute_immediate_return_command",
    "arguments": "{'working_directory': '/home/kavia/workspace', 'command': 'cd Authentication-server-I.0.3 && /usr/bin/python3 test_db.py'}",
    "reason": "Running the test script with the full path to python3 to verify our implementation.",
    "observations": "Testing the functionality of our database and models implementation using the full path to python3.",
    "root_cause_analysis": "",
    "data": "",
    "is_error": false
  },
  {
    "time": 1741875606336,
    "function_name": "execute_immediate_return_command",
    "arguments": "{'working_directory': '/home/kavia/workspace', 'command': 'find /home/kavia/workspace/Authentication-server-I.0.3/auth_core -type d | sort'}",
    "reason": "Checking the directory structure to understand the import issue.",
    "observations": "Checking the directory structure to understand why imports are not working correctly.",
    "root_cause_analysis": "",
    "data": "",
    "is_error": false
  },
  {
    "time": 1741875670852,
    "function_name": "execute_immediate_return_command",
    "arguments": "{'working_directory': '/home/kavia/workspace', 'command': 'cd Authentication-server-I.0.3 && /usr/bin/python3 test_db.py'}",
    "reason": "Running the test script again to verify our implementation after fixing the import issue.",
    "observations": "Testing the functionality of our database and models implementation after fixing the import issue.",
    "root_cause_analysis": "",
    "data": "",
    "is_error": false
  },
  {
    "time": 1741875692495,
    "function_name": "execute_immediate_return_command",
    "arguments": "{'working_directory': '/home/kavia/workspace', 'command': 'rm -f /home/kavia/workspace/Authentication-server-I.0.3/models.py /home/kavia/workspace/Authentication-server-I.0.3/test_db.py'}",
    "reason": "Cleaning up by removing the test script and the models.py file at the root level.",
    "observations": "Cleaning up temporary files that are no longer needed.",
    "root_cause_analysis": "",
    "data": "",
    "is_error": false
  },
  {
    "time": 1741875829679,
    "function_name": "execute_immediate_return_command",
    "arguments": "{'command': 'find /home/kavia/workspace/Authentication-server-I.0.3 -name \"*.py\" | grep -v \"__pycache__\" | xargs grep -l \"JWT\\\\\\\\|jwt\\\\\\\\|secret_key\\\\\\\\|SECRET_KEY\" 2>/dev/null || echo \"No JWT configuration files found\"', 'working_directory': '/home/kavia/workspace/Authentication-server-I.0.3'}",
    "reason": "Looking for any existing JWT configuration or secret key settings in the project",
    "observations": "Need to find if there's any existing JWT configuration to maintain consistency",
    "root_cause_analysis": "",
    "data": "",
    "is_error": false
  },
  {
    "time": 1741876210219,
    "function_name": "execute_immediate_return_command",
    "arguments": "{'command': 'ls -la /home/kavia/workspace/Authentication-server-I.0.3/auth_core/', 'working_directory': '/home/kavia/workspace/Authentication-server-I.0.3'}",
    "reason": "Checking if auth.py and security.py already exist",
    "observations": "Checking the directory structure to see if the files already exist",
    "root_cause_analysis": "",
    "data": "",
    "is_error": false
  },
  {
    "time": 1741876456144,
    "function_name": "execute_immediate_return_command",
    "arguments": "{'working_directory': '/home/kavia/workspace/Authentication-server-I.0.3', 'command': 'ls -la /home/kavia/workspace/Authentication-server-I.0.3/auth_core/auth.py /home/kavia/workspace/Authentication-server-I.0.3/auth_core/security.py'}",
    "reason": "Verifying that the files have been created correctly",
    "observations": "Checking if the files were created successfully",
    "root_cause_analysis": "",
    "data": "",
    "is_error": false
  },
  {
    "time": 1741876879933,
    "function_name": "execute_immediate_return_command",
    "arguments": "{'command': 'ls -la /home/kavia/workspace/Authentication-server-I.0.3/', 'working_directory': '/home/kavia/workspace/Authentication-server-I.0.3'}",
    "reason": "To understand the project structure and see what files already exist",
    "observations": "I need to see the project structure to understand what files already exist and what needs to be created or modified.",
    "root_cause_analysis": "",
    "data": "",
    "is_error": false
  },
  {
    "time": 1741876888049,
    "function_name": "execute_immediate_return_command",
    "arguments": "{'working_directory': '/home/kavia/workspace/Authentication-server-I.0.3', 'command': 'find auth_core -type f | sort'}",
    "reason": "To understand the auth_core directory structure",
    "observations": "I need to see what files exist in the auth_core directory to understand the current structure.",
    "root_cause_analysis": "",
    "data": "",
    "is_error": false
  },
  {
    "time": 1741876937172,
    "function_name": "execute_immediate_return_command",
    "arguments": "{'working_directory': '/home/kavia/workspace/Authentication-server-I.0.3', 'command': 'ls -la /home/kavia/workspace/Authentication-server-I.0.3/auth_core/config.py 2>/dev/null || echo \"File does not exist\"'}",
    "reason": "To check if config.py already exists",
    "observations": "I need to check if config.py already exists in the auth_core directory.",
    "root_cause_analysis": "",
    "data": "",
    "is_error": false
  },
  {
    "time": 1741876946540,
    "function_name": "execute_immediate_return_command",
    "arguments": "{'working_directory': '/home/kavia/workspace/Authentication-server-I.0.3', 'command': 'ls -la /home/kavia/workspace/Authentication-server-I.0.3/.env.example 2>/dev/null || echo \"File does not exist\"'}",
    "reason": "To check if .env.example already exists",
    "observations": "I need to check if .env.example already exists in the project root.",
    "root_cause_analysis": "",
    "data": "",
    "is_error": false
  },
  {
    "time": 1741877717511,
    "function_name": "execute_immediate_return_command",
    "arguments": "{'working_directory': '/home/kavia/workspace/Authentication-server-I.0.3', 'command': 'cd /home/kavia/workspace/Authentication-server-I.0.3 && python -m pytest tests/ -v'}",
    "reason": "Running the tests to verify they work",
    "observations": "Running the tests to verify they work correctly",
    "root_cause_analysis": "",
    "data": "",
    "is_error": false
  },
  {
    "time": 1741877729440,
    "function_name": "execute_immediate_return_command",
    "arguments": "{'working_directory': '/home/kavia/workspace/Authentication-server-I.0.3', 'command': 'cd /home/kavia/workspace/Authentication-server-I.0.3 && python3 -m pytest tests/ -v'}",
    "reason": "Running the tests with python3",
    "observations": "Running the tests with python3 to verify they work correctly",
    "root_cause_analysis": "",
    "data": "",
    "is_error": false
  },
  {
    "time": 1741878033032,
    "function_name": "execute_immediate_return_command",
    "arguments": "{'command': 'mkdir -p /home/kavia/workspace/Authentication-server-I.0.3/.github/workflows', 'working_directory': '/home/kavia/workspace/Authentication-server-I.0.3'}",
    "reason": "Creating directory for GitHub Actions workflow file",
    "observations": "Need to create the directory structure for GitHub Actions workflow",
    "root_cause_analysis": "",
    "data": "",
    "is_error": false
  },
  {
    "time": 1741880721660,
    "function_name": "execute_immediate_return_command",
    "arguments": "{'command': 'cd /home/kavia/workspace/Authentication-server-I.0.3 && python -c \"from auth_core import auth, token; print(\\'Import successful!\\')\"', 'working_directory': '/home/kavia/workspace/Authentication-server-I.0.3'}",
    "reason": "Testing if the circular import issue has been resolved by importing both modules",
    "observations": "No previous failures observed",
    "root_cause_analysis": "If the circular import issue is fixed, we should be able to import both modules without any errors",
    "data": "",
    "is_error": false
  },
  {
    "time": 1741880738985,
    "function_name": "execute_immediate_return_command",
    "arguments": "{'working_directory': '/home/kavia/workspace/Authentication-server-I.0.3', 'command': 'cd /home/kavia/workspace/Authentication-server-I.0.3 && python3 -c \"from auth_core import auth, token; print(\\'Import successful!\\')\"'}",
    "reason": "Testing if the circular import issue has been resolved by importing both modules using python3",
    "observations": "Previous command failed because 'python' command was not found",
    "root_cause_analysis": "If the circular import issue is fixed, we should be able to import both modules without any errors",
    "data": "",
    "is_error": false
  },
  {
    "time": 1741880754164,
    "function_name": "execute_immediate_return_command",
    "arguments": "{'working_directory': '/home/kavia/workspace/Authentication-server-I.0.3', 'command': 'cd /home/kavia/workspace/Authentication-server-I.0.3 && python3 -c \"import sys; sys.path.append(\\'/home/kavia/workspace/Authentication-server-I.0.3\\'); from auth_core.auth import TokenError; from auth_core.token import TokenError; print(\\'Import successful!\\')\"'}",
    "reason": "Testing the specific modules directly to check if the circular import issue is resolved",
    "observations": "Previous import failed due to unrelated project setup issues",
    "root_cause_analysis": "By importing just the specific modules we modified, we can check if our changes fixed the circular import issue",
    "data": "",
    "is_error": false
  },
  {
    "time": 1741880784147,
    "function_name": "execute_immediate_return_command",
    "arguments": "{'working_directory': '/home/kavia/workspace/Authentication-server-I.0.3', 'command': 'cd /home/kavia/workspace/Authentication-server-I.0.3 && python3 test_circular_import.py'}",
    "reason": "Running the test script to check if the circular import issue is resolved",
    "observations": "Created a simple test script to check if the circular import issue is resolved",
    "root_cause_analysis": "The test script will try to import both modules directly and report if it's successful",
    "data": "",
    "is_error": false
  },
  {
    "time": 1741880825974,
    "function_name": "execute_immediate_return_command",
    "arguments": "{'working_directory': '/home/kavia/workspace/Authentication-server-I.0.3', 'command': 'cd /home/kavia/workspace/Authentication-server-I.0.3 && python3 test_modules.py'}",
    "reason": "Running the isolated test script to check if the circular import issue is resolved",
    "observations": "Created a more isolated test script that doesn't depend on the full project setup",
    "root_cause_analysis": "This script directly examines the file structure without importing them, which avoids the project setup issues",
    "data": "",
    "is_error": false
  },
  {
    "time": 1741880973343,
    "function_name": "execute_immediate_return_command",
    "arguments": "{'command': 'head -20 /home/kavia/workspace/Authentication-server-I.0.3/auth_core/dependencies.py', 'working_directory': '/home/kavia/workspace/Authentication-server-I.0.3'}",
    "reason": "Verifying that the time module import has been moved to the top of the file",
    "observations": "No previous failures observed",
    "root_cause_analysis": "",
    "data": "",
    "is_error": false
  },
  {
    "time": 1741880980221,
    "function_name": "execute_immediate_return_command",
    "arguments": "{'working_directory': '/home/kavia/workspace/Authentication-server-I.0.3', 'command': 'tail -10 /home/kavia/workspace/Authentication-server-I.0.3/auth_core/dependencies.py'}",
    "reason": "Checking if the time module import has been removed from the end of the file",
    "observations": "No previous failures observed",
    "root_cause_analysis": "",
    "data": "",
    "is_error": false
  },
  {
    "time": 1741881181712,
    "function_name": "execute_immediate_return_command",
    "arguments": "{'command': 'cd /home/kavia/workspace/Authentication-server-I.0.3 && python test_circular_import.py', 'working_directory': '/home/kavia/workspace/Authentication-server-I.0.3'}",
    "reason": "Running the test script to reproduce the error",
    "observations": "Running the test script to see if we can reproduce the circular import error",
    "root_cause_analysis": "No failures yet, trying to reproduce the error",
    "data": "",
    "is_error": false
  },
  {
    "time": 1741881191814,
    "function_name": "execute_immediate_return_command",
    "arguments": "{'working_directory': '/home/kavia/workspace/Authentication-server-I.0.3', 'command': 'cd /home/kavia/workspace/Authentication-server-I.0.3 && python3 test_circular_import.py'}",
    "reason": "Running the test script to reproduce the error with python3",
    "observations": "Running the test script to see if we can reproduce the circular import error",
    "root_cause_analysis": "No failures yet, trying to reproduce the error with python3",
    "data": "",
    "is_error": false
  },
  {
    "time": 1741881275908,
    "function_name": "execute_immediate_return_command",
    "arguments": "{'working_directory': '/home/kavia/workspace/Authentication-server-I.0.3', 'command': 'cd /home/kavia/workspace/Authentication-server-I.0.3 && python3 test_circular_import.py'}",
    "reason": "Running the test script to verify the fix",
    "observations": "Running the test script to see if the circular import issue is resolved",
    "root_cause_analysis": "We've reordered the imports in auth_core/__init__.py to prevent circular dependencies",
    "data": "",
    "is_error": false
  },
  {
    "time": 1741881308019,
    "function_name": "execute_immediate_return_command",
    "arguments": "{'working_directory': '/home/kavia/workspace/Authentication-server-I.0.3', 'command': 'cd /home/kavia/workspace/Authentication-server-I.0.3 && python3 test_import_order.py'}",
    "reason": "Running the test script to verify the import order",
    "observations": "Running the test script to see if the import order is correct",
    "root_cause_analysis": "We've reordered the imports in auth_core/__init__.py to prevent circular dependencies",
    "data": "",
    "is_error": false
  },
  {
    "time": 1741881334933,
    "function_name": "execute_immediate_return_command",
    "arguments": "{'working_directory': '/home/kavia/workspace/Authentication-server-I.0.3', 'command': 'cd /home/kavia/workspace/Authentication-server-I.0.3 && python3 test_asyncio.py'}",
    "reason": "Running the test script to verify that the asyncio error is resolved",
    "observations": "Running the test script to see if the asyncio error is resolved",
    "root_cause_analysis": "We've reordered the imports in auth_core/__init__.py to prevent circular dependencies",
    "data": "",
    "is_error": false
  },
  {
    "time": 1741881361169,
    "function_name": "execute_immediate_return_command",
    "arguments": "{'working_directory': '/home/kavia/workspace/Authentication-server-I.0.3', 'command': 'cd /home/kavia/workspace/Authentication-server-I.0.3 && python3 test_auth_core_import.py'}",
    "reason": "Running the test script to verify that the auth_core module can be imported",
    "observations": "Running the test script to see if the auth_core module can be imported",
    "root_cause_analysis": "We've reordered the imports in auth_core/__init__.py to prevent circular dependencies",
    "data": "",
    "is_error": false
  },
  {
    "time": 1741881545827,
    "function_name": "execute_immediate_return_command",
    "arguments": "{'command': 'cd /home/kavia/workspace/Authentication-server-I.0.3 && python test_circular_import.py', 'working_directory': '/home/kavia/workspace/Authentication-server-I.0.3'}",
    "reason": "Testing if the circular import issue is resolved",
    "observations": "Running the test script to check if both modules can be imported successfully",
    "root_cause_analysis": "",
    "data": "",
    "is_error": false
  },
  {
    "time": 1741881556030,
    "function_name": "execute_immediate_return_command",
    "arguments": "{'working_directory': '/home/kavia/workspace/Authentication-server-I.0.3', 'command': 'cd /home/kavia/workspace/Authentication-server-I.0.3 && python3 test_circular_import.py'}",
    "reason": "Testing if the circular import issue is resolved using python3 command",
    "observations": "Running the test script with python3 to check if both modules can be imported successfully",
    "root_cause_analysis": "",
    "data": "",
    "is_error": false
  },
  {
    "time": 1741881566317,
    "function_name": "execute_immediate_return_command",
    "arguments": "{'working_directory': '/home/kavia/workspace/Authentication-server-I.0.3', 'command': 'cd /home/kavia/workspace/Authentication-server-I.0.3 && python3 test_asyncio.py'}",
    "reason": "Testing if the asyncio error is resolved",
    "observations": "Running the test script to check if asyncio.iscoroutine is available",
    "root_cause_analysis": "",
    "data": "",
    "is_error": false
  },
  {
    "time": 1741881588895,
    "function_name": "execute_immediate_return_command",
    "arguments": "{'working_directory': '/home/kavia/workspace/Authentication-server-I.0.3', 'command': 'cd /home/kavia/workspace/Authentication-server-I.0.3 && python3 test_api_import.py'}",
    "reason": "Testing if the api module can be imported without circular import issues",
    "observations": "Running the test script to check if the api module can be imported without circular import issues",
    "root_cause_analysis": "",
    "data": "",
    "is_error": false
  },
  {
    "time": 1741881719278,
    "function_name": "execute_immediate_return_command",
    "arguments": "{'working_directory': '/home/kavia/workspace', 'command': 'cd /home/kavia/workspace/Authentication-server-I.0.3 && python3 main.py'}",
    "reason": "Running the main application to verify that the asyncio error is resolved.",
    "observations": "I need to check if the application starts without the 'AttributeError: partially initialized module 'asyncio' has no attribute 'iscoroutine'' error.",
    "root_cause_analysis": "",
    "data": "",
    "is_error": false
  },
  {
    "time": 1741881765760,
    "function_name": "execute_immediate_return_command",
    "arguments": "{'working_directory': '/home/kavia/workspace', 'command': 'pip install pydantic-settings'}",
    "reason": "Installing the pydantic-settings package which is required for Pydantic v2.",
    "observations": "We need to install the pydantic-settings package to resolve the import error.",
    "root_cause_analysis": "The error occurs because BaseSettings has been moved to the pydantic-settings package in Pydantic v2, but this package is not installed.",
    "data": "",
    "is_error": false
  },
  {
    "time": 1741881809918,
    "function_name": "execute_immediate_return_command",
    "arguments": "{'working_directory': '/home/kavia/workspace', 'command': 'cd /home/kavia/workspace/Authentication-server-I.0.3 && python3 main.py'}",
    "reason": "Running the main application to verify that the asyncio error is resolved.",
    "observations": "We need to check if the application starts without errors after fixing the BaseSettings import.",
    "root_cause_analysis": "We've fixed the import for BaseSettings, now we need to check if the application runs without the asyncio error.",
    "data": "",
    "is_error": false
  },
  {
    "time": 1741881821516,
    "function_name": "execute_immediate_return_command",
    "arguments": "{'working_directory': '/home/kavia/workspace/Authentication-server-I.0.3', 'command': 'ls -la .env'}",
    "reason": "Checking if there's a .env file with environment variables causing validation errors.",
    "observations": "We need to check if there's a .env file with environment variables causing the validation errors.",
    "root_cause_analysis": "The error shows validation errors for ACCESS_TOKEN_EXPIRE_MINUTES and REFRESH_TOKEN_EXPIRE_DAYS, which might be set in a .env file.",
    "data": "",
    "is_error": false
  },
  {
    "time": 1741881863649,
    "function_name": "execute_immediate_return_command",
    "arguments": "{'working_directory': '/home/kavia/workspace', 'command': 'cd /home/kavia/workspace/Authentication-server-I.0.3 && python3 main.py'}",
    "reason": "Running the main application to verify that the asyncio error is resolved.",
    "observations": "We need to check if the application starts without errors after fixing the environment variable names.",
    "root_cause_analysis": "We've fixed the environment variable names in the Settings class, now we need to check if the application runs without errors.",
    "data": "",
    "is_error": false
  },
  {
    "time": 1741881891793,
    "function_name": "execute_immediate_return_command",
    "arguments": "{'working_directory': '/home/kavia/workspace', 'command': 'cd /home/kavia/workspace/Authentication-server-I.0.3 && python3 main.py'}",
    "reason": "Running the main application to verify that the asyncio error is resolved.",
    "observations": "We need to check if the application starts without errors after updating the Settings class configuration.",
    "root_cause_analysis": "We've updated the Settings class to use model_config with extra='ignore', now we need to check if the application runs without errors.",
    "data": "",
    "is_error": true
  },
  {
    "time": 1741882022468,
    "function_name": "start_long_running_process",
    "arguments": "{'working_directory': '/home/kavia/workspace', 'command': 'cd /home/kavia/workspace/Authentication-server-I.0.3 && python3 main.py'}",
    "reason": "Running the main application to verify that the asyncio error is resolved.",
    "observations": "We need to check if the application starts without errors after updating the Settings class configuration.",
    "root_cause_analysis": "The previous command timed out, which might indicate that the application is running successfully. Let's use start_long_running_process to see the output.",
    "data": "",
    "is_error": false
  },
  {
    "time": 1741882095407,
    "function_name": "execute_immediate_return_command",
    "arguments": "{'working_directory': '/home/kavia/workspace', 'command': 'cd /home/kavia/workspace/Authentication-server-I.0.3 && python3 test_asyncio.py'}",
    "reason": "Running the test script to verify that the asyncio error is resolved.",
    "observations": "We need to run the test script to verify that the asyncio error is resolved.",
    "root_cause_analysis": "We need to run the test script to verify that the asyncio error is resolved.",
    "data": "",
    "is_error": false
  },
  {
    "time": 1741882120526,
    "function_name": "execute_immediate_return_command",
    "arguments": "{'working_directory': '/home/kavia/workspace', 'command': 'cd /home/kavia/workspace/Authentication-server-I.0.3 && python3 test_circular_import.py'}",
    "reason": "Running the test script to verify that the circular import issue is resolved.",
    "observations": "We need to run the test script to verify that the circular import issue is resolved.",
    "root_cause_analysis": "We need to run the test script to verify that the circular import issue is resolved.",
    "data": "",
    "is_error": false
  },
  {
    "time": 1741886201941,
    "function_name": "execute_immediate_return_command",
    "arguments": "{'command': 'grep -n \"pydantic-settings\" /home/kavia/workspace/Authentication-server-I.0.3/pyproject.toml /home/kavia/workspace/Authentication-server-I.0.3/requirements.txt', 'working_directory': '/home/kavia/workspace/Authentication-server-I.0.3'}",
    "reason": "Verifying that pydantic-settings has been added to both files",
    "observations": "Checking if the package was successfully added to both files",
    "root_cause_analysis": "",
    "data": "",
    "is_error": false
  },
  {
    "time": 1741886802463,
    "function_name": "execute_immediate_return_command",
    "arguments": "{'command': 'grep -n \"model_config\" /home/kavia/workspace/Authentication-server-I.0.3/auth_core/config/settings.py', 'working_directory': '/home/kavia/workspace/Authentication-server-I.0.3'}",
    "reason": "Checking for Pydantic v2-specific configuration that might need compatibility handling",
    "observations": "Looking for model_config which is a Pydantic v2 feature that replaced Config class in v1",
    "root_cause_analysis": "",
    "data": "",
    "is_error": false
  },
  {
    "time": 1741886833064,
    "function_name": "execute_immediate_return_command",
    "arguments": "{'working_directory': '/home/kavia/workspace/Authentication-server-I.0.3', 'command': 'grep -n \"validator\" /home/kavia/workspace/Authentication-server-I.0.3/auth_core/config/settings.py'}",
    "reason": "Checking for other Pydantic v2-specific features that might need compatibility handling",
    "observations": "Looking for validator usage which might need compatibility handling between Pydantic v1 and v2",
    "root_cause_analysis": "",
    "data": "",
    "is_error": false
  },
  {
    "time": 1741886843347,
    "function_name": "execute_immediate_return_command",
    "arguments": "{'working_directory': '/home/kavia/workspace/Authentication-server-I.0.3', 'command': 'grep -n \"from pydantic import\" /home/kavia/workspace/Authentication-server-I.0.3/auth_core/config/settings.py'}",
    "reason": "Checking for other imports that might need compatibility handling",
    "observations": "Looking for other Pydantic imports that might need compatibility handling",
    "root_cause_analysis": "",
    "data": "",
    "is_error": false
  },
  {
    "time": 1741886853591,
    "function_name": "execute_immediate_return_command",
    "arguments": "{'working_directory': '/home/kavia/workspace/Authentication-server-I.0.3', 'command': 'python -c \"from auth_core.config.settings import get_settings; print(\\'Import successful\\')\"'}",
    "reason": "Testing if the modified settings.py file can be imported without errors",
    "observations": "Testing if our compatibility layer works correctly",
    "root_cause_analysis": "",
    "data": "",
    "is_error": false
  },
  {
    "time": 1741886975921,
    "function_name": "execute_immediate_return_command",
    "arguments": "{'command': 'pip list | grep pydantic', 'working_directory': '/home/kavia/workspace/Authentication-server-I.0.3'}",
    "reason": "Checking if pydantic-settings is installed in the environment",
    "observations": "Need to verify if the pydantic-settings package is installed",
    "root_cause_analysis": "",
    "data": "",
    "is_error": false
  },
  {
    "time": 1741886986551,
    "function_name": "start_long_running_process",
    "arguments": "{'working_directory': '/home/kavia/workspace/Authentication-server-I.0.3', 'command': 'python main.py'}",
    "reason": "Running the application to verify that the pydantic_settings error is resolved",
    "observations": "Starting the application to check if it runs without the ModuleNotFoundError for pydantic_settings",
    "root_cause_analysis": "",
    "data": "",
    "is_error": false
  },
  {
    "time": 1741887015756,
    "function_name": "execute_immediate_return_command",
    "arguments": "{'working_directory': '/home/kavia/workspace/Authentication-server-I.0.3', 'command': 'which python3'}",
    "reason": "Checking which Python versions are available",
    "observations": "Finding the path to the Python 3 executable",
    "root_cause_analysis": "Need to determine the correct Python command to use",
    "data": "",
    "is_error": false
  },
  {
    "time": 1741887053382,
    "function_name": "execute_immediate_return_command",
    "arguments": "{'working_directory': '/home/kavia/workspace', 'command': 'cd Authentication-server-I.0.3 && python3 test_settings.py'}",
    "reason": "Running the test script to verify that the pydantic_settings module can be imported and the Settings class works correctly",
    "observations": "Running the test script to check if pydantic_settings can be imported and the Settings class works",
    "root_cause_analysis": "Using a test script to verify if the pydantic_settings error is resolved",
    "data": "",
    "is_error": false
  },
  {
    "time": 1741887103679,
    "function_name": "execute_immediate_return_command",
    "arguments": "{'working_directory': '/home/kavia/workspace', 'command': 'cd Authentication-server-I.0.3 && python3 test_settings.py'}",
    "reason": "Running the test script again to verify that the pydantic_settings error is resolved",
    "observations": "Running the test script to check if the Settings class now works correctly with pydantic_settings",
    "root_cause_analysis": "We've fixed the issue by removing the Config class and keeping only the model_config dictionary, now we need to verify if the error is resolved",
    "data": "",
    "is_error": false
  },
  {
    "time": 1741887116301,
    "function_name": "execute_immediate_return_command",
    "arguments": "{'working_directory': '/home/kavia/workspace', 'command': 'cd Authentication-server-I.0.3 && uvicorn main:app --host 0.0.0.0 --port 8000 --no-server-header'}",
    "reason": "Checking if we can run the main application with uvicorn directly",
    "observations": "Running the application with uvicorn to check if it starts without the ModuleNotFoundError for pydantic_settings",
    "root_cause_analysis": "We need to verify that the main application can run without errors",
    "data": "",
    "is_error": true
  },
  {
    "time": 1741887248902,
    "function_name": "execute_immediate_return_command",
    "arguments": "{'working_directory': '/home/kavia/workspace', 'command': 'cd Authentication-server-I.0.3 && python3 -c \"import main; print(\\'Application loaded successfully!\\')\"'}",
    "reason": "Checking if the application can be loaded without errors using uvicorn's check mode",
    "observations": "Using Python to import the main module to check if it loads without the ModuleNotFoundError for pydantic_settings",
    "root_cause_analysis": "We need to verify that the main application can be loaded without errors",
    "data": "",
    "is_error": false
  },
  {
    "time": 1741887295275,
    "function_name": "execute_immediate_return_command",
    "arguments": "{'working_directory': '/home/kavia/workspace', 'command': 'cd Authentication-server-I.0.3 && python3 test_app_startup.py'}",
    "reason": "Running the comprehensive test script to verify that the application can start up properly",
    "observations": "Running the comprehensive test script to check if all components of the application work correctly",
    "root_cause_analysis": "We need to verify that all components of the application can start up properly",
    "data": "",
    "is_error": false
  },
  {
    "time": 1741887344482,
    "function_name": "execute_immediate_return_command",
    "arguments": "{'working_directory': '/home/kavia/workspace', 'command': 'cd Authentication-server-I.0.3 && python3 test_app_startup.py'}",
    "reason": "Running the updated test script to verify that the application can start up properly",
    "observations": "Running the updated test script to check if all components of the application work correctly",
    "root_cause_analysis": "We've fixed the test script to use get_session instead of get_db, now we need to verify if all tests pass",
    "data": "",
    "is_error": false
  },
  {
    "time": 1741888492116,
    "function_name": "execute_immediate_return_command",
    "arguments": "{'command': 'find /home/kavia/workspace/Authentication-server-I.0.3/auth_core -name \"*.py\" | sort', 'working_directory': '/home/kavia/workspace/Authentication-server-I.0.3'}",
    "reason": "Need to list all Python files in the auth_core package to identify potential modules using asyncio",
    "observations": "Looking for all Python files in the auth_core package to identify potential modules using asyncio.",
    "root_cause_analysis": "",
    "data": "",
    "is_error": false
  },
  {
    "time": 1741888687649,
    "function_name": "execute_immediate_return_command",
    "arguments": "{'command': 'cd /home/kavia/workspace/Authentication-server-I.0.3 && python test_asyncio.py', 'working_directory': '/home/kavia/workspace/Authentication-server-I.0.3'}",
    "reason": "Running the test_asyncio.py script to verify that the asyncio error is resolved",
    "observations": "No previous failures observed",
    "root_cause_analysis": "",
    "data": "",
    "is_error": false
  },
  {
    "time": 1741888696291,
    "function_name": "execute_immediate_return_command",
    "arguments": "{'working_directory': '/home/kavia/workspace/Authentication-server-I.0.3', 'command': 'cd /home/kavia/workspace/Authentication-server-I.0.3 && python3 test_asyncio.py'}",
    "reason": "Running the test_asyncio.py script with python3 to verify that the asyncio error is resolved",
    "observations": "Previous command failed because 'python' command was not found",
    "root_cause_analysis": "",
    "data": "",
    "is_error": false
  },
  {
    "time": 1741888705708,
    "function_name": "execute_immediate_return_command",
    "arguments": "{'working_directory': '/home/kavia/workspace/Authentication-server-I.0.3', 'command': 'cd /home/kavia/workspace/Authentication-server-I.0.3 && python3 test_circular_import.py'}",
    "reason": "Running the test_circular_import.py script to verify that the circular import issue is resolved",
    "observations": "No previous failures observed",
    "root_cause_analysis": "",
    "data": "",
    "is_error": false
  },
  {
    "time": 1741888716002,
    "function_name": "execute_immediate_return_command",
    "arguments": "{'working_directory': '/home/kavia/workspace/Authentication-server-I.0.3', 'command': 'cd /home/kavia/workspace/Authentication-server-I.0.3 && python3 test_import_order.py'}",
    "reason": "Running the test_import_order.py script to verify that the import order is correct",
    "observations": "No previous failures observed",
    "root_cause_analysis": "",
    "data": "",
    "is_error": false
  },
  {
    "time": 1741889029508,
    "function_name": "execute_immediate_return_command",
    "arguments": "{'command': 'cd /home/kavia/workspace/Authentication-server-I.0.3 && python -c \"import auth_core.dependencies; print(\\'Dependencies module imported successfully\\')\"', 'working_directory': '/home/kavia/workspace/Authentication-server-I.0.3'}",
    "reason": "Testing if the circular import issue has been resolved by importing the dependencies module",
    "observations": "After modifying dependencies.py to use function-level imports, we need to verify that the circular import issue has been resolved.",
    "root_cause_analysis": "The circular import issue should be resolved by moving the imports inside functions. This test will verify if the module can be imported without errors.",
    "data": "",
    "is_error": false
  },
  {
    "time": 1741889040450,
    "function_name": "execute_immediate_return_command",
    "arguments": "{'working_directory': '/home/kavia/workspace/Authentication-server-I.0.3', 'command': 'cd /home/kavia/workspace/Authentication-server-I.0.3 && python3 -c \"import auth_core.dependencies; print(\\'Dependencies module imported successfully\\')\"'}",
    "reason": "Testing if the circular import issue has been resolved by importing the dependencies module using python3",
    "observations": "After modifying dependencies.py to use function-level imports, we need to verify that the circular import issue has been resolved.",
    "root_cause_analysis": "The circular import issue should be resolved by moving the imports inside functions. This test will verify if the module can be imported without errors.",
    "data": "",
    "is_error": false
  },
  {
    "time": 1741889053315,
    "function_name": "execute_immediate_return_command",
    "arguments": "{'working_directory': '/home/kavia/workspace/Authentication-server-I.0.3', 'command': 'cd /home/kavia/workspace/Authentication-server-I.0.3 && python3 -c \"import auth_core.auth; print(\\'Auth module imported successfully\\')\"'}",
    "reason": "Testing if the circular import issue has been resolved by importing the auth module",
    "observations": "After modifying dependencies.py to use function-level imports, we need to verify that the circular import issue has been resolved for the auth module as well.",
    "root_cause_analysis": "The circular import issue should be resolved by moving the imports inside functions. This test will verify if the auth module can be imported without errors.",
    "data": "",
    "is_error": false
  },
  {
    "time": 1741889065369,
    "function_name": "execute_immediate_return_command",
    "arguments": "{'working_directory': '/home/kavia/workspace/Authentication-server-I.0.3', 'command': 'cd /home/kavia/workspace/Authentication-server-I.0.3 && python3 -c \"import auth_core.token; print(\\'Token module imported successfully\\')\"'}",
    "reason": "Testing if the circular import issue has been resolved by importing the token module",
    "observations": "After modifying dependencies.py to use function-level imports, we need to verify that the circular import issue has been resolved for the token module as well.",
    "root_cause_analysis": "The circular import issue should be resolved by moving the imports inside functions. This test will verify if the token module can be imported without errors.",
    "data": "",
    "is_error": false
  },
  {
    "time": 1741889077891,
    "function_name": "execute_immediate_return_command",
    "arguments": "{'working_directory': '/home/kavia/workspace/Authentication-server-I.0.3', 'command': 'cd /home/kavia/workspace/Authentication-server-I.0.3 && python3 -c \"import auth_core.dependencies; import auth_core.token; import auth_core.auth; print(\\'All modules imported successfully\\')\"'}",
    "reason": "Testing if the circular import issue has been resolved by importing all three modules together",
    "observations": "After modifying dependencies.py to use function-level imports, we need to verify that all three modules can be imported together without circular import issues.",
    "root_cause_analysis": "The circular import issue should be resolved by moving the imports inside functions. This test will verify if all three modules can be imported together without errors.",
    "data": "",
    "is_error": false
  },
  {
    "time": 1741889133309,
    "function_name": "execute_immediate_return_command",
    "arguments": "{'command': 'ls -la /home/kavia/workspace/Authentication-server-I.0.3/', 'working_directory': '/home/kavia/workspace/Authentication-server-I.0.3'}",
    "reason": "Checking the directory structure to understand the project layout",
    "observations": "I need to understand the project structure before running tests",
    "root_cause_analysis": "",
    "data": "",
    "is_error": false
  },
  {
    "time": 1741889177253,
    "function_name": "start_long_running_process",
    "arguments": "{'working_directory': '/home/kavia/workspace/Authentication-server-I.0.3', 'command': 'python test_asyncio.py'}",
    "reason": "Running the test_asyncio.py to check if the asyncio error is resolved",
    "observations": "This test checks if asyncio.iscoroutine is available",
    "root_cause_analysis": "",
    "data": "",
    "is_error": false
  },
  {
    "time": 1741889206768,
    "function_name": "execute_immediate_return_command",
    "arguments": "{'working_directory': '/home/kavia/workspace/Authentication-server-I.0.3', 'command': 'which python3'}",
    "reason": "Checking available Python versions",
    "observations": "Need to find the correct Python executable",
    "root_cause_analysis": "",
    "data": "",
    "is_error": false
  },
  {
    "time": 1741889215302,
    "function_name": "execute_immediate_return_command",
    "arguments": "{'working_directory': '/home/kavia/workspace/Authentication-server-I.0.3', 'command': 'which pytest'}",
    "reason": "Checking if pytest is available",
    "observations": "Need to find the correct pytest executable",
    "root_cause_analysis": "",
    "data": "",
    "is_error": false
  },
  {
    "time": 1741889226206,
    "function_name": "start_long_running_process",
    "arguments": "{'working_directory': '/home/kavia/workspace/Authentication-server-I.0.3', 'command': 'cd /home/kavia/workspace/Authentication-server-I.0.3 && python3 -m pytest test_asyncio.py test_circular_import.py test_modules.py test_import_order.py test_api_import.py test_auth_core_import.py -v'}",
    "reason": "Running the test files with pytest to check if the asyncio error is resolved",
    "observations": "Running all the specified test files with pytest in verbose mode",
    "root_cause_analysis": "",
    "data": "",
    "is_error": false
  },
  {
    "time": 1741889255167,
    "function_name": "execute_immediate_return_command",
    "arguments": "{'working_directory': '/home/kavia/workspace/Authentication-server-I.0.3', 'command': 'cd /home/kavia/workspace/Authentication-server-I.0.3 && python3 test_asyncio.py'}",
    "reason": "Running test_asyncio.py directly",
    "observations": "Running the asyncio test directly with python3",
    "root_cause_analysis": "",
    "data": "",
    "is_error": false
  },
  {
    "time": 1741889263482,
    "function_name": "execute_immediate_return_command",
    "arguments": "{'working_directory': '/home/kavia/workspace/Authentication-server-I.0.3', 'command': 'cd /home/kavia/workspace/Authentication-server-I.0.3 && python3 test_circular_import.py'}",
    "reason": "Running test_circular_import.py directly",
    "observations": "Running the circular import test directly with python3",
    "root_cause_analysis": "",
    "data": "",
    "is_error": false
  },
  {
    "time": 1741889273214,
    "function_name": "execute_immediate_return_command",
    "arguments": "{'working_directory': '/home/kavia/workspace/Authentication-server-I.0.3', 'command': 'cd /home/kavia/workspace/Authentication-server-I.0.3 && python3 test_modules.py'}",
    "reason": "Running test_modules.py directly",
    "observations": "Running the modules test directly with python3",
    "root_cause_analysis": "",
    "data": "",
    "is_error": false
  },
  {
    "time": 1741889282053,
    "function_name": "execute_immediate_return_command",
    "arguments": "{'working_directory': '/home/kavia/workspace/Authentication-server-I.0.3', 'command': 'cd /home/kavia/workspace/Authentication-server-I.0.3 && python3 test_import_order.py'}",
    "reason": "Running test_import_order.py directly",
    "observations": "Running the import order test directly with python3",
    "root_cause_analysis": "",
    "data": "",
    "is_error": false
  },
  {
    "time": 1741889293431,
    "function_name": "execute_immediate_return_command",
    "arguments": "{'working_directory': '/home/kavia/workspace/Authentication-server-I.0.3', 'command': 'cd /home/kavia/workspace/Authentication-server-I.0.3 && python3 test_api_import.py'}",
    "reason": "Running test_api_import.py directly",
    "observations": "Running the API import test directly with python3",
    "root_cause_analysis": "",
    "data": "",
    "is_error": false
  },
  {
    "time": 1741889303707,
    "function_name": "execute_immediate_return_command",
    "arguments": "{'working_directory': '/home/kavia/workspace/Authentication-server-I.0.3', 'command': 'cd /home/kavia/workspace/Authentication-server-I.0.3 && python3 test_auth_core_import.py'}",
    "reason": "Running test_auth_core_import.py directly",
    "observations": "Running the auth_core import test directly with python3",
    "root_cause_analysis": "",
    "data": "",
    "is_error": false
  },
  {
    "time": 1741889317556,
    "function_name": "start_long_running_process",
    "arguments": "{'working_directory': '/home/kavia/workspace/Authentication-server-I.0.3', 'command': 'cd /home/kavia/workspace/Authentication-server-I.0.3 && python3 main.py'}",
    "reason": "Running the main application to verify it starts without asyncio errors",
    "observations": "This will start the main application to verify there are no asyncio errors during startup",
    "root_cause_analysis": "",
    "data": "",
    "is_error": false
  },
  {
    "time": 1741889394300,
    "function_name": "execute_immediate_return_command",
    "arguments": "{'working_directory': '/home/kavia/workspace/Authentication-server-I.0.3', 'command': 'cd /home/kavia/workspace/Authentication-server-I.0.3 && python3 test_app_startup.py'}",
    "reason": "Running test_app_startup.py to verify the application can start up properly",
    "observations": "This test verifies that the application can start up properly without any errors",
    "root_cause_analysis": "",
    "data": "",
    "is_error": false
  },
  {
    "time": 1741889407466,
    "function_name": "execute_immediate_return_command",
    "arguments": "{'working_directory': '/home/kavia/workspace/Authentication-server-I.0.3', 'command': 'ls -la /home/kavia/workspace/Authentication-server-I.0.3/tests/'}",
    "reason": "Checking for unit tests in the tests directory",
    "observations": "Need to check if there are any unit tests that should be run",
    "root_cause_analysis": "",
    "data": "",
    "is_error": false
  },
  {
    "time": 1741889420781,
    "function_name": "start_long_running_process",
    "arguments": "{'working_directory': '/home/kavia/workspace/Authentication-server-I.0.3', 'command': 'cd /home/kavia/workspace/Authentication-server-I.0.3 && python3 -m pytest tests/ -v'}",
    "reason": "Running the unit tests to verify there are no asyncio errors",
    "observations": "Running the unit tests in the tests directory to verify there are no asyncio errors",
    "root_cause_analysis": "",
    "data": "",
    "is_error": false
  },
  {
    "time": 1741892032493,
    "function_name": "execute_immediate_return_command",
    "arguments": "{'command': 'ls -la /home/kavia/workspace/Authentication-server-I.0.3', 'working_directory': '/home/kavia/workspace/Authentication-server-I.0.3'}",
    "reason": "To understand the project structure and identify key directories and files",
    "observations": "Starting with a directory listing to understand the project structure",
    "root_cause_analysis": "",
    "data": "",
    "is_error": false
  },
  {
    "time": 1741892047943,
    "function_name": "execute_immediate_return_command",
    "arguments": "{'working_directory': '/home/kavia/workspace/Authentication-server-I.0.3/tests', 'command': 'cd .. && python3 -m pytest tests/ -v'}",
    "reason": "To run the failing tests and see the specific errors",
    "observations": "Running the test command from the tests directory to see which tests are failing and why",
    "root_cause_analysis": "",
    "data": "",
    "is_error": false
  },
  {
    "time": 1741892098548,
    "function_name": "execute_immediate_return_command",
    "arguments": "{'working_directory': '/home/kavia/workspace/Authentication-server-I.0.3/tests', 'command': 'ls -la'}",
    "reason": "To understand the test directory structure",
    "observations": "Examining the test directory structure to understand the organization of test files",
    "root_cause_analysis": "",
    "data": "",
    "is_error": false
  },
  {
    "time": 1741892585428,
    "function_name": "execute_immediate_return_command",
    "arguments": "{'command': 'cd /home/kavia/workspace/Authentication-server-I.0.3 && python -m pytest tests/test_auth.py -v', 'working_directory': '/home/kavia/workspace/Authentication-server-I.0.3'}",
    "reason": "Need to check if there are any failing tests related to password hashing",
    "observations": "No previous failures observed",
    "root_cause_analysis": "",
    "data": "",
    "is_error": false
  },
  {
    "time": 1741892593957,
    "function_name": "execute_immediate_return_command",
    "arguments": "{'working_directory': '/home/kavia/workspace/Authentication-server-I.0.3', 'command': 'cd /home/kavia/workspace/Authentication-server-I.0.3 && python3 -m pytest tests/test_auth.py -v'}",
    "reason": "Need to check if there are any failing tests related to password hashing",
    "observations": "No previous failures observed",
    "root_cause_analysis": "",
    "data": "",
    "is_error": false
  },
  {
    "time": 1741892680277,
    "function_name": "execute_immediate_return_command",
    "arguments": "{'working_directory': '/home/kavia/workspace/Authentication-server-I.0.3', 'command': 'cd /home/kavia/workspace/Authentication-server-I.0.3 && python3 -m pytest tests/test_auth.py::test_authenticate_user_success -v'}",
    "reason": "Need to check if the fix resolved the password hashing issue in tests",
    "observations": "No previous failures observed",
    "root_cause_analysis": "",
    "data": "",
    "is_error": false
  },
  {
    "time": 1741892718800,
    "function_name": "execute_immediate_return_command",
    "arguments": "{'working_directory': '/home/kavia/workspace/Authentication-server-I.0.3', 'command': 'cd /home/kavia/workspace/Authentication-server-I.0.3 && python3 -m pytest tests/test_auth.py::test_authenticate_user_success -v'}",
    "reason": "Need to check if the fix resolved the password hashing issue in tests",
    "observations": "No previous failures observed",
    "root_cause_analysis": "",
    "data": "",
    "is_error": false
  },
  {
    "time": 1741892818272,
    "function_name": "execute_immediate_return_command",
    "arguments": "{'working_directory': '/home/kavia/workspace/Authentication-server-I.0.3', 'command': 'cd /home/kavia/workspace/Authentication-server-I.0.3 && python3 -m pytest tests/test_auth.py::test_authenticate_user_success -v'}",
    "reason": "Need to check if the fix resolved the password hashing issue in tests",
    "observations": "No previous failures observed",
    "root_cause_analysis": "",
    "data": "",
    "is_error": false
  },
  {
    "time": 1741892891586,
    "function_name": "execute_immediate_return_command",
    "arguments": "{'working_directory': '/home/kavia/workspace/Authentication-server-I.0.3', 'command': 'cd /home/kavia/workspace/Authentication-server-I.0.3 && python3 -m pytest tests/test_auth.py::test_authenticate_user_success -v'}",
    "reason": "Need to check if the fix resolved the password hashing issue in tests",
    "observations": "No previous failures observed",
    "root_cause_analysis": "",
    "data": "",
    "is_error": false
  },
  {
    "time": 1741893232950,
    "function_name": "execute_immediate_return_command",
    "arguments": "{'command': 'cd /home/kavia/workspace/Authentication-server-I.0.3 && python -m pytest tests/test_auth.py -v', 'working_directory': '/home/kavia/workspace/Authentication-server-I.0.3'}",
    "reason": "Running the authentication tests to verify that our changes have fixed the failing tests.",
    "observations": "Executing the authentication tests to check if our changes have resolved the issues.",
    "root_cause_analysis": "",
    "data": "",
    "is_error": false
  },
  {
    "time": 1741893242905,
    "function_name": "execute_immediate_return_command",
    "arguments": "{'working_directory': '/home/kavia/workspace/Authentication-server-I.0.3', 'command': 'cd /home/kavia/workspace/Authentication-server-I.0.3 && python3 -m pytest tests/test_auth.py -v'}",
    "reason": "Running the authentication tests with python3 to verify that our changes have fixed the failing tests.",
    "observations": "Executing the authentication tests with python3 to check if our changes have resolved the issues.",
    "root_cause_analysis": "",
    "data": "",
    "is_error": false
  },
  {
    "time": 1741893356806,
    "function_name": "execute_immediate_return_command",
    "arguments": "{'working_directory': '/home/kavia/workspace/Authentication-server-I.0.3', 'command': 'cd /home/kavia/workspace/Authentication-server-I.0.3 && python3 -m pytest tests/test_auth.py::test_register_user_success tests/test_auth.py::test_register_user_with_auto_login -v'}",
    "reason": "Running the authentication tests again to verify that our changes have fixed the failing tests.",
    "observations": "Executing specific tests related to user registration to check if our changes have resolved the issues.",
    "root_cause_analysis": "",
    "data": "",
    "is_error": false
  },
  {
    "time": 1741893419733,
    "function_name": "execute_immediate_return_command",
    "arguments": "{'working_directory': '/home/kavia/workspace/Authentication-server-I.0.3', 'command': 'cd /home/kavia/workspace/Authentication-server-I.0.3 && python3 -m pytest tests/test_auth.py::test_register_user_success tests/test_auth.py::test_register_user_with_auto_login -v'}",
    "reason": "Running the authentication tests again to verify that our changes have fixed the failing tests.",
    "observations": "Executing specific tests related to user registration to check if our changes have resolved the issues.",
    "root_cause_analysis": "",
    "data": "",
    "is_error": false
  },
  {
    "time": 1741893491914,
    "function_name": "execute_immediate_return_command",
    "arguments": "{'working_directory': '/home/kavia/workspace/Authentication-server-I.0.3', 'command': 'cd /home/kavia/workspace/Authentication-server-I.0.3 && python3 -m pytest tests/test_auth.py::test_register_user_success tests/test_auth.py::test_register_user_with_auto_login -v'}",
    "reason": "Running the authentication tests again to verify that our changes have fixed the failing tests.",
    "observations": "Executing specific tests related to user registration to check if our changes have resolved the issues.",
    "root_cause_analysis": "",
    "data": "",
    "is_error": false
  },
  {
    "time": 1741893572762,
    "function_name": "execute_immediate_return_command",
    "arguments": "{'working_directory': '/home/kavia/workspace/Authentication-server-I.0.3', 'command': 'cd /home/kavia/workspace/Authentication-server-I.0.3 && python3 -m pytest tests/test_auth.py::test_register_user_success tests/test_auth.py::test_register_user_with_auto_login -v'}",
    "reason": "Running the authentication tests again to verify that our changes have fixed the failing tests.",
    "observations": "Executing specific tests related to user registration to check if our changes have resolved the issues.",
    "root_cause_analysis": "",
    "data": "",
    "is_error": false
  },
  {
    "time": 1741894016596,
    "function_name": "execute_immediate_return_command",
    "arguments": "{'command': 'echo \"Changes made to token.py to improve token validation and revocation methods\"', 'working_directory': '/home/kavia/workspace/Authentication-server-I.0.3'}",
    "reason": "Summarizing the changes made to token.py",
    "observations": "Summarizing the changes made to token.py to improve token validation and revocation methods",
    "root_cause_analysis": "",
    "data": "",
    "is_error": false
  },
  {
    "time": 1741894075048,
    "function_name": "execute_immediate_return_command",
    "arguments": "{'command': 'ls -la /home/kavia/workspace/Authentication-server-I.0.3', 'working_directory': '/home/kavia/workspace/Authentication-server-I.0.3'}",
    "reason": "Exploring the project structure to understand the codebase organization",
    "observations": "No previous failures observed. Starting fresh exploration.",
    "root_cause_analysis": "",
    "data": "",
    "is_error": false
  },
  {
    "time": 1741894085981,
    "function_name": "execute_immediate_return_command",
    "arguments": "{'working_directory': '/home/kavia/workspace/Authentication-server-I.0.3', 'command': 'ls -la /home/kavia/workspace/Authentication-server-I.0.3/tests/'}",
    "reason": "Examining the test directory structure to understand the test organization",
    "observations": "No previous failures observed. Exploring test directory structure.",
    "root_cause_analysis": "",
    "data": "",
    "is_error": false
  },
  {
    "time": 1741894093383,
    "function_name": "execute_immediate_return_command",
    "arguments": "{'working_directory': '/home/kavia/workspace/Authentication-server-I.0.3', 'command': 'ls -la /home/kavia/workspace/Authentication-server-I.0.3/auth_core/'}",
    "reason": "Examining the auth_core directory to understand the application structure",
    "observations": "No previous failures observed. Exploring application structure.",
    "root_cause_analysis": "",
    "data": "",
    "is_error": false
  },
  {
    "time": 1741894118671,
    "function_name": "start_long_running_process",
    "arguments": "{'working_directory': '/home/kavia/workspace/Authentication-server-I.0.3', 'command': 'python -m pytest tests/ -v'}",
    "reason": "Running the complete test suite to verify all fixes",
    "observations": "No previous failures observed. Running the test suite as requested.",
    "root_cause_analysis": "",
    "data": "",
    "is_error": false
  },
  {
    "time": 1741894141866,
    "function_name": "execute_immediate_return_command",
    "arguments": "{'working_directory': '/home/kavia/workspace/Authentication-server-I.0.3', 'command': 'which python3 python'}",
    "reason": "Checking available Python commands",
    "observations": "Previous command failed with 'python: command not found'. Checking available Python commands.",
    "root_cause_analysis": "The previous command failed because 'python' command was not found. Need to check what Python commands are available.",
    "data": "",
    "is_error": false
  },
  {
    "time": 1741894152125,
    "function_name": "start_long_running_process",
    "arguments": "{'working_directory': '/home/kavia/workspace/Authentication-server-I.0.3', 'command': 'cd /home/kavia/workspace/Authentication-server-I.0.3 && python3 -m pytest tests/ -v'}",
    "reason": "Running the complete test suite with python3 command",
    "observations": "Previous command failed with 'python: command not found'. Using python3 instead.",
    "root_cause_analysis": "The previous command failed because 'python' command was not found. Using 'python3' instead which is available at /usr/bin/python3.",
    "data": "",
    "is_error": false
  },
  {
    "time": 1741894444827,
    "function_name": "execute_immediate_return_command",
    "arguments": "{'command': 'cd /home/kavia/workspace/Authentication-server-I.0.3 && python -m pytest tests/test_auth.py -v', 'working_directory': '/home/kavia/workspace/Authentication-server-I.0.3'}",
    "reason": "Running the authentication tests to see which specific tests are failing.",
    "observations": "Running the tests to identify the failing tests related to password verification.",
    "root_cause_analysis": "",
    "data": "",
    "is_error": false
  },
  {
    "time": 1741894454090,
    "function_name": "execute_immediate_return_command",
    "arguments": "{'working_directory': '/home/kavia/workspace/Authentication-server-I.0.3', 'command': 'cd /home/kavia/workspace/Authentication-server-I.0.3 && python3 -m pytest tests/test_auth.py -v'}",
    "reason": "Running the authentication tests with python3 to see which specific tests are failing.",
    "observations": "Running the tests with python3 to identify the failing tests related to password verification.",
    "root_cause_analysis": "",
    "data": "",
    "is_error": false
  },
  {
    "time": 1741894537262,
    "function_name": "execute_immediate_return_command",
    "arguments": "{'working_directory': '/home/kavia/workspace/Authentication-server-I.0.3', 'command': 'cd /home/kavia/workspace/Authentication-server-I.0.3 && python3 -m pytest tests/test_auth.py::test_authenticate_user_success tests/test_auth.py::test_authenticate_user_with_email tests/test_auth.py::test_change_password -v'}",
    "reason": "Running the authentication tests again to verify that our changes fixed the password verification issues.",
    "observations": "Running specific tests that were failing due to password verification issues to see if our changes fixed the problems.",
    "root_cause_analysis": "",
    "data": "",
    "is_error": false
  },
  {
    "time": 1741894586132,
    "function_name": "execute_immediate_return_command",
    "arguments": "{'working_directory': '/home/kavia/workspace', 'command': 'cd /home/kavia/workspace/Authentication-server-I.0.3 && python3 -c \"import bcrypt; print(f\\'bcrypt version: {bcrypt.__version__}\\')\"'}",
    "reason": "Checking the bcrypt version to ensure it's compatible with the code.",
    "observations": "Checking the bcrypt version to ensure it's compatible with the code.",
    "root_cause_analysis": "The password verification is still failing, which might be due to incompatible bcrypt versions or incorrect usage.",
    "data": "",
    "is_error": false
  },
  {
    "time": 1741894596517,
    "function_name": "execute_immediate_return_command",
    "arguments": "{'working_directory': '/home/kavia/workspace', 'command': 'cd /home/kavia/workspace/Authentication-server-I.0.3 && python3 -c \"import passlib; print(f\\'passlib version: {passlib.__version__}\\')\"'}",
    "reason": "Checking the passlib version to ensure it's compatible with the code.",
    "observations": "Checking the passlib version to ensure it's compatible with the code.",
    "root_cause_analysis": "The password verification is still failing, which might be due to incompatible passlib versions or incorrect usage.",
    "data": "",
    "is_error": false
  },
  {
    "time": 1741894657816,
    "function_name": "execute_immediate_return_command",
    "arguments": "{'working_directory': '/home/kavia/workspace', 'command': 'cd /home/kavia/workspace/Authentication-server-I.0.3 && python3 -m pytest tests/test_auth.py::test_authenticate_user_success tests/test_auth.py::test_authenticate_user_with_email tests/test_auth.py::test_change_password -v'}",
    "reason": "Running the authentication tests again to verify that our changes fixed the password verification issues.",
    "observations": "Running specific tests that were failing due to password verification issues to see if our changes fixed the problems.",
    "root_cause_analysis": "",
    "data": "",
    "is_error": false
  },
  {
    "time": 1741894741845,
    "function_name": "execute_immediate_return_command",
    "arguments": "{'working_directory': '/home/kavia/workspace', 'command': 'cd /home/kavia/workspace/Authentication-server-I.0.3 && python3 -m pytest tests/test_auth.py::test_authenticate_user_success tests/test_auth.py::test_authenticate_user_with_email tests/test_auth.py::test_change_password -v'}",
    "reason": "Running the authentication tests again to verify that our changes fixed the password verification issues.",
    "observations": "Running specific tests that were failing due to password verification issues to see if our changes fixed the problems.",
    "root_cause_analysis": "",
    "data": "",
    "is_error": false
  }
]